Sun Oct  8 14:51:10 2023
Linux-6.2.0-34-generic-x86_64-with-glibc2.35
Ren'Py 8.1.0.23051307
 

Bootstrap to the start of init.init. took 0.06s
Early init. took 0.00s
Loader init. took 0.01s
Loading error handling. took 0.04s
Loading script. took 0.60s
Loading save slot metadata. took 0.03s
Loading persistent. took 0.00s
Set script version to: None (alternate path)
Running init code. took 0.54s
Loading analysis data. took 0.04s
Analyze and compile ATL. took 0.01s
Reloading save slot metadata. took 0.02s
Index archives took 0.00s
Dump and make backups. took 0.00s
Cleaning cache. took 0.00s
Making clean stores. took 0.00s
Initial gc. took 0.04s
DPI scale factor: 1.000000
Creating interface object. took 0.00s
Cleaning stores took 0.00s
Init translation took 0.05s
Build styles took 0.00s
Load screen analysis took 0.06s
Analyze screens took 0.00s
Save screen analysis took 0.00s
Prepare screens took 0.15s
Save pyanalysis. took 0.00s
Save bytecode. took 0.00s
Running _start took 0.00s
Performance test:
Interface start. took 0.32s

Initializing gl2 renderer:
primary display bounds: (0, 0, 1920, 1080)
swap interval: 1 frames
Windowed mode.
Vendor: "b'NVIDIA Corporation'"
Renderer: b'NVIDIA GeForce GTX 1660 Ti/PCIe/SSE2'
Version: b'4.6.0 NVIDIA 525.125.06'
Display Info: None
Screen sizes: virtual=(800, 600) physical=(800, 600) drawable=(800, 600)
Maximum texture size: 4096x4096
----
Traceback (most recent call last):
  File "/home/tom/ab/renpy-build/tmp/install.linux-x86_64/lib/python3.9/site-packages/urllib3/connection.py", line 140, in _new_conn
  File "/home/tom/ab/renpy-build/tmp/install.linux-x86_64/lib/python3.9/site-packages/urllib3/util/connection.py", line 83, in create_connection
  File "/home/tom/ab/renpy-build/tmp/install.linux-x86_64/lib/python3.9/site-packages/urllib3/util/connection.py", line 73, in create_connection
TimeoutError: [Errno 110] Connection timed out

During handling of the above exception, another exception occurred:

Traceback (most recent call last):
  File "/home/tom/ab/renpy-build/tmp/install.linux-x86_64/lib/python3.9/site-packages/urllib3/connectionpool.py", line 598, in urlopen
  File "/home/tom/ab/renpy-build/tmp/install.linux-x86_64/lib/python3.9/site-packages/urllib3/connectionpool.py", line 346, in _make_request
  File "/home/tom/ab/renpy-build/tmp/install.linux-x86_64/lib/python3.9/site-packages/urllib3/connectionpool.py", line 850, in _validate_conn
  File "/home/tom/ab/renpy-build/tmp/install.linux-x86_64/lib/python3.9/site-packages/urllib3/connection.py", line 284, in connect
  File "/home/tom/ab/renpy-build/tmp/install.linux-x86_64/lib/python3.9/site-packages/urllib3/connection.py", line 149, in _new_conn
urllib3.exceptions.NewConnectionError: <urllib3.connection.VerifiedHTTPSConnection object at 0x7f345bbd4070>: Failed to establish a new connection: [Errno 110] Connection timed out

During handling of the above exception, another exception occurred:

Traceback (most recent call last):
  File "/home/tom/ab/renpy-build/tmp/install.linux-x86_64/lib/python3.9/site-packages/requests/adapters.py", line 439, in send
  File "/home/tom/ab/renpy-build/tmp/install.linux-x86_64/lib/python3.9/site-packages/urllib3/connectionpool.py", line 638, in urlopen
  File "/home/tom/ab/renpy-build/tmp/install.linux-x86_64/lib/python3.9/site-packages/urllib3/util/retry.py", line 388, in increment
urllib3.exceptions.MaxRetryError: HTTPSConnectionPool(host='www.renpy.org', port=443): Max retries exceeded with url: /channels.json (Caused by NewConnectionError('<urllib3.connection.VerifiedHTTPSConnection object at 0x7f345bbd4070>: Failed to establish a new connection: [Errno 110] Connection timed out'))

During handling of the above exception, another exception occurred:

Traceback (most recent call last):
  File "/home/sirano/Документы/V-N/vis-novel/renpy/exports.py", line 3928, in run
    fn(*args, **kwargs)
  File "game/updater.rpy", line 223, in fetch_update_channels
  File "/home/tom/ab/renpy-build/tmp/install.linux-x86_64/lib/python3.9/site-packages/requests/api.py", line 75, in get
  File "/home/tom/ab/renpy-build/tmp/install.linux-x86_64/lib/python3.9/site-packages/requests/api.py", line 60, in request
  File "/home/tom/ab/renpy-build/tmp/install.linux-x86_64/lib/python3.9/site-packages/requests/sessions.py", line 524, in request
  File "/home/tom/ab/renpy-build/tmp/install.linux-x86_64/lib/python3.9/site-packages/requests/sessions.py", line 637, in send
  File "/home/tom/ab/renpy-build/tmp/install.linux-x86_64/lib/python3.9/site-packages/requests/adapters.py", line 516, in send
requests.exceptions.ConnectionError: HTTPSConnectionPool(host='www.renpy.org', port=443): Max retries exceeded with url: /channels.json (Caused by NewConnectionError('<urllib3.connection.VerifiedHTTPSConnection object at 0x7f345bbd4070>: Failed to establish a new connection: [Errno 110] Connection timed out'))
----
